{"name": "test_Verify_error_displayed_when_invalid_password_entered[data1]", "status": "failed", "statusDetails": {"message": "AssertionError", "trace": "self = <tests.test_login_adata_valid_and_invalid.Test_Login_Data object at 0x000001A82588BF70>, data = ['+639654257082', 'isinvalid']\n\n    @pytest.mark.parametrize('data', Testdata.valid_un_invalid_pw())\n    def test_Verify_error_displayed_when_invalid_password_entered(self, data):\n        login_panel = test_login.Test_login_panel(self.driver)\n        login_panel.enter_user_credential(data[0])\n        login_panel.click_login_button()\n        login_panel.enter_password(data[1])\n        login_panel.click_login_button()\n>       login_panel.verify_error_is_displayed_invalid_password_input()\n\ntests\\test_login_adata_valid_and_invalid.py:34: \n_ _ _ _ _ _ _ _ _ _ _ _ _ _ _ _ _ _ _ _ _ _ _ _ _ _ _ _ _ _ _ _ _ _ _ _ _ _ _ _ _ _ _ _ _ _ _ _ _ _ _ _ _ _ _ _ _ _ _ _ _ _ _ _ _ _ _ _ _ _ _ _ _ _ _ _ _ _ _ _ _ _ _ _ _ _ _ _ _ _ _ _ _ _ _ _ _ _ _ _ _ _ _ _ _ _ _ _ _ _ _ _ _ _ _ _ _ \nPageObject\\LoginPage\\test_login.py:100: in verify_error_is_displayed_invalid_password_input\n    self.assert_correct_text_is_displayed(invalidpass, \"Incorrect password. Please try again.\")\n_ _ _ _ _ _ _ _ _ _ _ _ _ _ _ _ _ _ _ _ _ _ _ _ _ _ _ _ _ _ _ _ _ _ _ _ _ _ _ _ _ _ _ _ _ _ _ _ _ _ _ _ _ _ _ _ _ _ _ _ _ _ _ _ _ _ _ _ _ _ _ _ _ _ _ _ _ _ _ _ _ _ _ _ _ _ _ _ _ _ _ _ _ _ _ _ _ _ _ _ _ _ _ _ _ _ _ _ _ _ _ _ _ _ _ _ _ \n\nself = <PageObject.LoginPage.test_login.Test_login_panel object at 0x000001A8258DD0D0>\nvalue = <selenium.webdriver.remote.webelement.WebElement (session=\"f18f6c6c9d27d3c6781ead632e88b161\", element=\"135012fb-d12d-4c48-b078-1fc63b23e919\")>, expected = 'Incorrect password. Please try again.'\n\n    def assert_correct_text_is_displayed(self, value, expected):\n        if value.text == expected:\n            assert True\n        else:\n            self.attach_screenshot(\"Bug Detected\")\n>           assert False\nE           AssertionError\n\nutilities\\BaseClass.py:29: AssertionError"}, "attachments": [{"name": "data was entered", "source": "a67d3fe3-d68d-4373-8622-7bbe3b7e7e52-attachment.png", "type": "image/png"}, {"name": "data was entered", "source": "077018c4-f258-4a3b-983d-35a2c2546252-attachment.png", "type": "image/png"}, {"name": "Bug Detected", "source": "7fb3d924-3f2e-4ef8-a78e-b0bf806e4152-attachment.png", "type": "image/png"}], "parameters": [{"name": "data", "value": "['+639654257082', 'isinvalid']"}], "start": 1623561536900, "stop": 1623561543015, "uuid": "d167a760-1ec1-4339-a18d-e37c56fd4243", "historyId": "a1031b2baab6db0cfafca88ce8d7739c", "testCaseId": "b6c8b3e51b072b623dd51f21e8815dd1", "fullName": "tests.test_login_adata_valid_and_invalid.Test_Login_Data#test_Verify_error_displayed_when_invalid_password_entered", "labels": [{"name": "tag", "value": "@pytest.mark.usefixtures('setup')"}, {"name": "parentSuite", "value": "tests"}, {"name": "suite", "value": "test_login_adata_valid_and_invalid"}, {"name": "subSuite", "value": "Test_Login_Data"}, {"name": "host", "value": "HazelYu"}, {"name": "thread", "value": "9108-MainThread"}, {"name": "framework", "value": "pytest"}, {"name": "language", "value": "cpython3"}, {"name": "package", "value": "tests.test_login_adata_valid_and_invalid"}]}